Workbook

Sheet Conclusion
A1: When we compare with update all and with update(electricity) only , there are no huge differences: 12% for RCP45 and 3% for Base scenarios (coupled with N1)
A2: RCP 45 | B2: electricity production, hydro, reservoir, alpine region
B3: heat and power co-generation, wood chips, 6667 kW
B4: electricity production, natural gas, combined cycle power plant
B5: and all storage technologies that are connected to market for elec >> loop
A6: Base | B6: electricity production, natural gas, combined cycle power plant
B7: market group for electricity, high voltage

Sheet elec 1 kWh
B1: db_name | C1: model | D1: IAM scenario | E1: FR scenario | F1: year | G1: warning | H1: act | I1: impact | J1: unit
A2: 0 | B2: ei_cutoff_3.9_tiam-ucl_SSP2-RCP45_2020_Reference - N1 2025-05-22 - elec | C2: tiam-ucl | D2: RCP45 | E2: N1 | F2: 2050 | G2: update electricity only | H2: market for electricity, high voltage, FE2050 | I2: 0.014394858 | J2: kg CO2-Eq | K2: =(I2-I4)/I4 -> 0.11695841
A3: 1 | B3: ei_cutoff_3.9_tiam-ucl_SSP2-Base_2050_Reference - N1 2025-05-22 - elec | C3: tiam-ucl | D3: Base | E3: N1 | F3: 2050 | G3: update electricity only | H3: market for electricity, high voltage, FE2050 | I3: 0.029012976 | J3: kg CO2-Eq | K3: =(I3-I5)/I5 -> 0.026013463
A4: 2 | B4: ei_cutoff_3.9_tiam-ucl_SSP2-RCP45_2050_Reference - N1 2025-05-15 | C4: tiam-ucl | D4: RCP45 | E4: N1 | F4: 2050 | H4: market for electricity, high voltage, FE2050 | I4: 0.012887551 | J4: kg CO2-Eq
A5: 3 | B5: ei_cutoff_3.9_tiam-ucl_SSP2-Base_2050_Reference - N1 2025-05-15 | C5: tiam-ucl | D5: Base | E5: N1 | F5: 2050 | H5: market for electricity, high voltage, FE2050 | I5: 0.028277384 | J5: kg CO2-Eq

Sheet contrib an. aggreg
B1: db_name | C1: model | D1: IAM scenario | E1: FR scenario | F1: year | G1: warning | H1: act | I1: impact | J1: unit | K1: amount (kWh) | L1: contribution to impact | M1: percentage
A2: 0 | B2: ei_cutoff_3.9_tiam-ucl_SSP2-RCP45_2020_Reference - N1 2025-05-22 - elec | C2: tiam-ucl | D2: RCP45 | E2: N1 | F2: 2050 | G2: update electricity only+wrong year in db.name | H2: market for electricity, high voltage, FE2050 | I2: 14.394858 | J2: g CO2-Eq | K2: 1 | L2: 14.394858 | M2: 99.999999
A3: 1 | B3: ei_cutoff_3.9_tiam-ucl_SSP2-RCP45_2020_Reference - N1 2025-05-22 - elec | C3: tiam-ucl | D3: RCP45 | E3: N1 | F3: 2050 | G3: update electricity only+wrong year in db.name | H3: market for electricity, from direct French production, FE2050 | I3: 13.219036 | J3: g CO2-Eq | K3: 0.90977795 | L3: 12.026388 | M3: 83.54641
A4: 2 | B4: ei_cutoff_3.9_tiam-ucl_SSP2-RCP45_2020_Reference - N1 2025-05-22 - elec | C4: tiam-ucl | D4: RCP45 | E4: N1 | F4: 2050 | G4: update electricity only+wrong year in db.name | H4: market for electricity, from storage, FE2050 | I4: 37.038309 | J4: g CO2-Eq | K4: 0.043975119 | L4: 1.628764 | M4: 11.314901
A5: 3 | B5: ei_cutoff_3.9_tiam-ucl_SSP2-RCP45_2020_Reference - N1 2025-05-22 - elec | C5: tiam-ucl | D5: RCP45 | E5: N1 | F5: 2050 | G5: update electricity only+wrong year in db.name | H5: market for electricity, from import, FE2050 | I5: 15.994724 | J5: g CO2-Eq | K5: 0.04624693 | L5: 0.73970687 | M5: 5.1386881
B7: db_name | C7: model | D7: IAM scenario | E7: FR scenario | F7: year | G7: warning | H7: act | I7: impact | J7: unit | K7: amount (kWh) | L7: contribution to impact | M7: percentage
A8: 0 | B8: ei_cutoff_3.9_tiam-ucl_SSP2-Base_2050_Reference - N1 2025-05-22 - elec | C8: tiam-ucl | D8: Base | E8: N1 | F8: 2050 | G8: update electricity only | H8: market for electricity, high voltage, FE2050 | I8: 29.012976 | J8: g CO2-Eq | K8: 1 | L8: 29.012976 | M8: 100
A9: 1 | B9: ei_cutoff_3.9_tiam-ucl_SSP2-Base_2050_Reference - N1 2025-05-22 - elec | C9: tiam-ucl | D9: Base | E9: N1 | F9: 2050 | G9: update electricity only | H9: market for electricity, from direct French production, FE2050 | I9: 14.134447 | J9: g CO2-Eq | K9: 0.90977795 | L9: 12.859208 | M9: 44.322265
A10: 2 | B10: ei_cutoff_3.9_tiam-ucl_SSP2-Base_2050_Reference - N1 2025-05-22 - elec | C10: tiam-ucl | D10: Base | E10: N1 | F10: 2050 | G10: update electricity only | H10: market for electricity, from storage, FE2050 | I10: 58.708416 | J10: g CO2-Eq | K10: 0.043975119 | L10: 2.5817096 | M10: 8.8984653
A11: 3 | B11: ei_cutoff_3.9_tiam-ucl_SSP2-Base_2050_Reference - N1 2025-05-22 - elec | C11: tiam-ucl | D11: Base | E11: N1 | F11: 2050 | G11: update electricity only | H11: market for electricity, from import, FE2050 | I11: 293.46939 | J11: g CO2-Eq | K11: 0.04624693 | L11: 13.572058 | M11: 46.77927
B13: db_name | C13: model | D13: IAM scenario | E13: FR scenario | F13: year | G13: warning | H13: act | I13: impact | J13: unit | K13: amount (kWh) | L13: contribution to impact | M13: percentage
A14: 0 | B14: ei_cutoff_3.9_tiam-ucl_SSP2-RCP45_2050_Reference - N1 2025-05-15 | C14: tiam-ucl | D14: RCP45 | E14: N1 | F14: 2050 | H14: market for electricity, high voltage, FE2050 | I14: 12.887551 | J14: g CO2-Eq | K14: 1 | L14: 12.887551 | M14: 99.999999
A15: 1 | B15: ei_cutoff_3.9_tiam-ucl_SSP2-RCP45_2050_Reference - N1 2025-05-15 | C15: tiam-ucl | D15: RCP45 | E15: N1 | F15: 2050 | H15: market for electricity, from direct French production, FE2050 | I15: 11.857105 | J15: g CO2-Eq | K15: 0.90977795 | L15: 10.787333 | M15: 83.703512
A16: 2 | B16: ei_cutoff_3.9_tiam-ucl_SSP2-RCP45_2050_Reference - N1 2025-05-15 | C16: tiam-ucl | D16: RCP45 | E16: N1 | F16: 2050 | H16: market for electricity, from storage, FE2050 | I16: 33.285022 | J16: g CO2-Eq | K16: 0.043975119 | L16: 1.4637128 | M16: 11.357571
A17: 3 | B17: ei_cutoff_3.9_tiam-ucl_SSP2-RCP45_2050_Reference - N1 2025-05-15 | C17: tiam-ucl | D17: RCP45 | E17: N1 | F17: 2050 | H17: market for electricity, from import, FE2050 | I17: 13.763193 | J17: g CO2-Eq | K17: 0.04624693 | L17: 0.63650542 | M17: 4.9389168
B19: db_name | C19: model | D19: IAM scenario | E19: FR scenario | F19: year | G19: warning | H19: act | I19: impact | J19: unit | K19: amount (kWh) | L19: contribution to impact | M19: percentage
A20: 0 | B20: ei_cutoff_3.9_tiam-ucl_SSP2-Base_2050_Reference - N1 2025-05-15 | C20: tiam-ucl | D20: Base | E20: N1 | F20: 2050 | H20: market for electricity, high voltage, FE2050 | I20: 28.277384 | J20: g CO2-Eq | K20: 1 | L20: 28.277384 | M20: 100
A21: 1 | B21: ei_cutoff_3.9_tiam-ucl_SSP2-Base_2050_Reference - N1 2025-05-15 | C21: tiam-ucl | D21: Base | E21: N1 | F21: 2050 | H21: market for electricity, from direct French production, FE2050 | I21: 13.911463 | J21: g CO2-Eq | K21: 0.90977795 | L21: 12.656342 | M21: 44.757827
A22: 2 | B22: ei_cutoff_3.9_tiam-ucl_SSP2-Base_2050_Reference - N1 2025-05-15 | C22: tiam-ucl | D22: Base | E22: N1 | F22: 2050 | H22: market for electricity, from storage, FE2050 | I22: 59.155208 | J22: g CO2-Eq | K22: 0.043975119 | L22: 2.6013574 | M22: 9.1994274
A23: 3 | B23: ei_cutoff_3.9_tiam-ucl_SSP2-Base_2050_Reference - N1 2025-05-15 | C23: tiam-ucl | D23: Base | E23: N1 | F23: 2050 | H23: market for electricity, from import, FE2050 | I23: 281.52536 | J23: g CO2-Eq | K23: 0.04624693 | L23: 13.019684 | M23: 46.042746

Sheet contrib an. detail
B1: db_name | C1: model | D1: IAM scenario | E1: FR scenario | F1: year | G1: warning | H1: act | I1: amount | J1: unit amount | K1: impact | L1: unit impact | M1: % impact | N1: absolute impact | O1: absolute impact/impact elec | R1: db_name | S1: model | T1: IAM scenario | U1: FR scenario | V1: year | W1: warning | X1: act | Y1: amount | Z1: unit amount | AA1: impact | AB1: unit impact | AC1: % impact | AD1: absolute impact | AE1: absolute impact/impact elec | AG1: impact 1 kWh | AH1: diff in absolute impact / total impact of consumption mix
A2: 0 | B2: ei_cutoff_3.9_tiam-ucl_SSP2-RCP45_2020_Reference - N1 2025-05-22 - elec | C2: tiam-ucl | D2: RCP45 | E2: N1 | F2: 2050 | G2: update electricity only+wrong year in db.name | H2: electricity production, nuclear, pressure water reactor | I2: 0.12384131 | J2: kilowatt hour | K2: 0.00054089374 | L2: kg CO2-Eq | M2: 0.037575482 | N2: 0.0043676358 | O2: 0.30341638 | Q2: 0 | R2: ei_cutoff_3.9_tiam-ucl_SSP2-RCP45_2050_Reference - N1 2025-05-15 | S2: tiam-ucl | T2: RCP45 | U2: N1 | V2: 2050 | X2: electricity production, nuclear, pressure water reactor | Y2: 0.12384131 | Z2: kilowatt hour | AA2: 0.00053143948 | AB2: kg CO2-Eq | AC2: 0.041236654 | AD2: 0.004291294 | AE2: 0.33297979 | AG2: =(K2-AA2)/AA2 -> 0.017789921 | AH2: =(N2-AD2)/('contrib an. aggreg'!$I$2/1000) -> 0.0053034063
A3: 1 | B3: ei_cutoff_3.9_tiam-ucl_SSP2-RCP45_2020_Reference - N1 2025-05-22 - elec | C3: tiam-ucl | D3: RCP45 | E3: N1 | F3: 2050 | G3: update electricity only+wrong year in db.name | H3: electricity production, Evolutionary Power Reactor (EPR) | I3: 0.12008855 | J3: kilowatt hour | K3: 0.00040310477 | L3: kg CO2-Eq | M3: 0.028003386 | N3: 0.0033567296 | O3: 0.23318948 | Q3: 1 | R3: ei_cutoff_3.9_tiam-ucl_SSP2-RCP45_2050_Reference - N1 2025-05-15 | S3: tiam-ucl | T3: RCP45 | U3: N1 | V3: 2050 | X3: electricity production, Evolutionary Power Reactor (EPR) | Y3: 0.12008855 | Z3: kilowatt hour | AA3: 0.00038453227 | AB3: kg CO2-Eq | AC3: 0.029837498 | AD3: 0.0032020729 | AE3: 0.24846248 | AG3: =(K3-AA3)/AA3 -> 0.048298945 | AH3: =(N3-AD3)/('contrib an. aggreg'!$I$2/1000) -> 0.010743888
A4: 2 | B4: ei_cutoff_3.9_tiam-ucl_SSP2-RCP45_2020_Reference - N1 2025-05-22 - elec | C4: tiam-ucl | D4: RCP45 | E4: N1 | F4: 2050 | G4: update electricity only+wrong year in db.name | H4: electricity production, hydro, run-of-river | I4: 0.070702131 | J4: kilowatt hour | K4: 0.00025040577 | L4: kg CO2-Eq | M4: 0.017395501 | N4: 0.0035417005 | O4: 0.24603928 | Q4: 2 | R4: ei_cutoff_3.9_tiam-ucl_SSP2-RCP45_2050_Reference - N1 2025-05-15 | S4: tiam-ucl | T4: RCP45 | U4: N1 | V4: 2050 | X4: electricity production, hydro, run-of-river | Y4: 0.070702131 | Z4: kilowatt hour | AA4: 0.00014731904 | AB4: kg CO2-Eq | AC4: 0.011431112 | AD4: 0.0020836577 | AE4: 0.16167988 | AG4: =(K4-AA4)/AA4 -> 0.6997516 | AH4: =(N4-AD4)/('contrib an. aggreg'!$I$2/1000) -> 0.10128914
A5: 3 | B5: ei_cutoff_3.9_tiam-ucl_SSP2-RCP45_2020_Reference - N1 2025-05-22 - elec | C5: tiam-ucl | D5: RCP45 | E5: N1 | F5: 2050 | G5: update electricity only+wrong year in db.name | H5: electricity production, hydro, reservoir, alpine region | I5: 0.013467073 | J5: kilowatt hour | K5: 7.1092797e-05 | L5: kg CO2-Eq | M5: 0.0049387633 | N5: 0.005279009 | O5: 0.36672879 | Q5: 3 | R5: ei_cutoff_3.9_tiam-ucl_SSP2-RCP45_2050_Reference - N1 2025-05-15 | S5: tiam-ucl | T5: RCP45 | U5: N1 | V5: 2050 | X5: electricity production, hydro, reservoir, alpine region | Y5: 0.013467073 | Z5: kilowatt hour | AA5: 3.707897e-05 | AB5: kg CO2-Eq | AC5: 0.0028771153 | AD5: 0.0027533059 | AE5: 0.21364074 | AG5: =(K5-AA5)/AA5 -> 0.91733472 | AH5: =(N5-AD5)/('contrib an. aggreg'!$I$2/1000) -> 0.1754587
A6: 4 | B6: ei_cutoff_3.9_tiam-ucl_SSP2-RCP45_2020_Reference - N1 2025-05-22 - elec | C6: tiam-ucl | D6: RCP45 | E6: N1 | F6: 2050 | G6: update electricity only+wrong year in db.name | H6: electricity production, photovoltaic | I6: 0.19353556 | J6: kilowatt hour | K6: 0.003156578 | L6: kg CO2-Eq | M6: 0.2192851 | N6: 0.016310068 | O6: 1.1330481 | Q6: 4 | R6: ei_cutoff_3.9_tiam-ucl_SSP2-RCP45_2050_Reference - N1 2025-05-15 | S6: tiam-ucl | T6: RCP45 | U6: N1 | V6: 2050 | X6: electricity production, photovoltaic | Y6: 0.19353556 | Z6: kilowatt hour | AA6: 0.0028979677 | AB6: kg CO2-Eq | AC6: 0.22486566 | AD6: 0.014973826 | AE6: 1.1618829 | AG6: =(K6-AA6)/AA6 -> 0.08923852 | AH6: =(N6-AD6)/('contrib an. aggreg'!$I$2/1000) -> 0.09282773
A7: 5 | B7: ei_cutoff_3.9_tiam-ucl_SSP2-RCP45_2020_Reference - N1 2025-05-22 - elec | C7: tiam-ucl | D7: RCP45 | E7: N1 | F7: 2050 | G7: update electricity only+wrong year in db.name | H7: electricity production, wind, 1-3MW turbine, onshore | I7: 0.15721413 | J7: kilowatt hour | K7: 0.0018003153 | L7: kg CO2-Eq | M7: 0.12506655 | N7: 0.011451358 | O7: 0.79551724 | Q7: 5 | R7: ei_cutoff_3.9_tiam-ucl_SSP2-RCP45_2050_Reference - N1 2025-05-15 | S7: tiam-ucl | T7: RCP45 | U7: N1 | V7: 2050 | X7: electricity production, wind, 1-3MW turbine, onshore | Y7: 0.15721413 | Z7: kilowatt hour | AA7: 0.0016594352 | AB7: kg CO2-Eq | AC7: 0.12876265 | AD7: 0.010555254 | AE7: 0.81902717 | AG7: =(K7-AA7)/AA7 -> 0.08489645 | AH7: =(N7-AD7)/('contrib an. aggreg'!$I$2/1000) -> 0.062251646
A8: 6 | B8: ei_cutoff_3.9_tiam-ucl_SSP2-RCP45_2020_Reference - N1 2025-05-22 - elec | C8: tiam-ucl | D8: RCP45 | E8: N1 | F8: 2050 | G8: update electricity only+wrong year in db.name | H8: electricity production, wind, 1-3MW turbine, offshore | I8: 0.21471189 | J8: kilowatt hour | K8: 0.0026761003 | L8: kg CO2-Eq | M8: 0.18590668 | N8: 0.01246368 | O8: 0.8658425 | Q8: 6 | R8: ei_cutoff_3.9_tiam-ucl_SSP2-RCP45_2050_Reference - N1 2025-05-15 | S8: tiam-ucl | T8: RCP45 | U8: N1 | V8: 2050 | X8: electricity production, wind, 1-3MW turbine, offshore | Y8: 0.21471189 | Z8: kilowatt hour | AA8: 0.0024086879 | AB8: kg CO2-Eq | AC8: 0.18690036 | AD8: 0.011218233 | AE8: 0.87047047 | AG8: =(K8-AA8)/AA8 -> 0.11101995 | AH8: =(N8-AD8)/('contrib an. aggreg'!$I$2/1000) -> 0.08652031
A9: 7 | B9: ei_cutoff_3.9_tiam-ucl_SSP2-RCP45_2020_Reference - N1 2025-05-22 - elec | C9: tiam-ucl | D9: RCP45 | E9: N1 | F9: 2050 | G9: update electricity only+wrong year in db.name | H9: heat and power co-generation, wood chips, 6667 kW | I9: 0.013134685 | J9: kilowatt hour | K9: 0.00073780007 | L9: kg CO2-Eq | M9: 0.051254417 | N9: 0.056171891 | O9: 3.9022191 | Q9: 7 | R9: ei_cutoff_3.9_tiam-ucl_SSP2-RCP45_2050_Reference - N1 2025-05-15 | S9: tiam-ucl | T9: RCP45 | U9: N1 | V9: 2050 | X9: heat and power co-generation, wood chips, 6667 kW | Y9: 0.013134685 | Z9: kilowatt hour | AA9: 0.00053832105 | AB9: kg CO2-Eq | AC9: 0.041770624 | AD9: 0.040984695 | AE9: 3.1801772 | AG9: =(K9-AA9)/AA9 -> 0.37055773 | AH9: =(N9-AD9)/('contrib an. aggreg'!$I$2/1000) -> 1.0550431
A10: 8 | B10: ei_cutoff_3.9_tiam-ucl_SSP2-RCP45_2020_Reference - N1 2025-05-22 - elec | C10: tiam-ucl | D10: RCP45 | E10: N1 | F10: 2050 | G10: update electricity only+wrong year in db.name | H10: treatment of municipal solid waste, incineration | I10: 0.0024124931 | J10: kilowatt hour | K10: 0 | L10: kg CO2-Eq | M10: 0 | N10: 0 | O10: 0 | Q10: 8 | R10: ei_cutoff_3.9_tiam-ucl_SSP2-RCP45_2050_Reference - N1 2025-05-15 | S10: tiam-ucl | T10: RCP45 | U10: N1 | V10: 2050 | X10: treatment of municipal solid waste, incineration | Y10: 0.0024124931 | Z10: kilowatt hour | AA10: 0 | AB10: kg CO2-Eq | AC10: 0 | AD10: 0 | AE10: 0 | AH10: =(N10-AD10)/('contrib an. aggreg'!$I$2/1000) -> 0
A11: 9 | B11: ei_cutoff_3.9_tiam-ucl_SSP2-RCP45_2020_Reference - N1 2025-05-22 - elec | C11: tiam-ucl | D11: RCP45 | E11: N1 | F11: 2050 | G11: update electricity only+wrong year in db.name | H11: electricity production, natural gas, combined cycle power plant | I11: 0.00067013697 | J11: kilowatt hour | K11: 4.4945959e-05 | L11: kg CO2-Eq | M11: 0.003122362 | N11: 0.067069809 | O11: 4.6592893 | Q11: 9 | R11: ei_cutoff_3.9_tiam-ucl_SSP2-RCP45_2050_Reference - N1 2025-05-15 | S11: tiam-ucl | T11: RCP45 | U11: N1 | V11: 2050 | X11: electricity production, natural gas, combined cycle power plant | Y11: 0.00067013697 | Z11: kilowatt hour | AA11: 2.599565e-05 | AB11: kg CO2-Eq | AC11: 0.0020171133 | AD11: 0.038791547 | AE11: 3.0100015 | AG11: =(K11-AA11)/AA11 -> 0.72898 | AH11: =(N11-AD11)/('contrib an. aggreg'!$I$2/1000) -> 1.9644696
A12: 10 | B12: ei_cutoff_3.9_tiam-ucl_SSP2-RCP45_2020_Reference - N1 2025-05-22 - elec | C12: tiam-ucl | D12: RCP45 | E12: N1 | F12: 2050 | G12: update electricity only+wrong year in db.name | H12: electricity production, hydro, pumped storage, FE2050 | I12: 0.021842905 | J12: kilowatt hour | K12: 0.0004595557 | L12: kg CO2-Eq | M12: 0.03192499 | N12: 0.02103913 | O12: 1.4615725 | Q12: 10 | R12: ei_cutoff_3.9_tiam-ucl_SSP2-RCP45_2050_Reference - N1 2025-05-15 | S12: tiam-ucl | T12: RCP45 | U12: N1 | V12: 2050 | X12: electricity production, hydro, pumped storage, FE2050 | Y12: 0.021842905 | Z12: kilowatt hour | AA12: 0.0003683404 | AB12: kg CO2-Eq | AC12: 0.028581102 | AD12: 0.01686316 | AE12: 1.3084845 | AG12: =(K12-AA12)/AA12 -> 0.24763859 | AH12: =(N12-AD12)/('contrib an. aggreg'!$I$2/1000) -> 0.29010145
A13: 11 | B13: ei_cutoff_3.9_tiam-ucl_SSP2-RCP45_2020_Reference - N1 2025-05-22 - elec | C13: tiam-ucl | D13: RCP45 | E13: N1 | F13: 2050 | G13: update electricity only+wrong year in db.name | H13: electricity production, from hydrogen, with gas turbine, for grid-balancing, FE2050 | I13: 0.0082453349 | J13: kilowatt hour | K13: 0.00049813093 | L13: kg CO2-Eq | M13: 0.034604782 | N13: 0.060413669 | O13: 4.1968922 | Q13: 11 | R13: ei_cutoff_3.9_tiam-ucl_SSP2-RCP45_2050_Reference - N1 2025-05-15 | S13: tiam-ucl | T13: RCP45 | U13: N1 | V13: 2050 | X13: electricity production, from hydrogen, with gas turbine, for grid-balancing, FE2050 | Y13: 0.0082453349 | Z13: kilowatt hour | AA13: 0.00046641282 | AB13: kg CO2-Eq | AC13: 0.036190958 | AD13: 0.056566874 | AE13: 4.3892648 | AG13: =(K13-AA13)/AA13 -> 0.068004377 | AH13: =(N13-AD13)/('contrib an. aggreg'!$I$2/1000) -> 0.26723396
A14: 12 | B14: ei_cutoff_3.9_tiam-ucl_SSP2-RCP45_2020_Reference - N1 2025-05-22 - elec | C14: tiam-ucl | D14: RCP45 | E14: N1 | F14: 2050 | G14: update electricity only+wrong year in db.name | H14: electricity production, from vehicle-to-grid, FE2050 | I14: 0.002748445 | J14: kilowatt hour | K14: 6.5502835e-05 | L14: kg CO2-Eq | M14: 0.0045504328 | N14: 0.023832689 | O14: 1.655639 | Q14: 12 | R14: ei_cutoff_3.9_tiam-ucl_SSP2-RCP45_2050_Reference - N1 2025-05-15 | S14: tiam-ucl | T14: RCP45 | U14: N1 | V14: 2050 | X14: electricity production, from vehicle-to-grid, FE2050 | Y14: 0.002748445 | Z14: kilowatt hour | AA14: 5.9707758e-05 | AB14: kg CO2-Eq | AC14: 0.0046329794 | AD14: 0.021724196 | AE14: 1.685673 | AG14: =(K14-AA14)/AA14 -> 0.097057351 | AH14: =(N14-AD14)/('contrib an. aggreg'!$I$2/1000) -> 0.14647542
A15: 13 | B15: ei_cutoff_3.9_tiam-ucl_SSP2-RCP45_2020_Reference - N1 2025-05-22 - elec | C15: tiam-ucl | D15: RCP45 | E15: N1 | F15: 2050 | G15: update electricity only+wrong year in db.name | H15: electricity supply, high voltage, from vanadium-redox flow battery system, FE2050 | I15: 0.011138435 | J15: kilowatt hour | K15: 0.00045949383 | L15: kg CO2-Eq | M15: 0.031920691 | N15: 0.041252998 | O15: 2.8658148 | Q15: 13 | R15: ei_cutoff_3.9_tiam-ucl_SSP2-RCP45_2050_Reference - N1 2025-05-15 | S15: tiam-ucl | T15: RCP45 | U15: N1 | V15: 2050 | X15: electricity supply, high voltage, from vanadium-redox flow battery system, FE2050 | Y15: 0.011138435 | Z15: kilowatt hour | AA15: 0.00043557253 | AB15: kg CO2-Eq | AC15: 0.033797929 | AD15: 0.039105362 | AE15: 3.0343517 | AG15: =(K15-AA15)/AA15 -> 0.054919214 | AH15: =(N15-AD15)/('contrib an. aggreg'!$I$2/1000) -> 0.14919464
A16: 14 | B16: ei_cutoff_3.9_tiam-ucl_SSP2-RCP45_2020_Reference - N1 2025-05-22 - elec | C16: tiam-ucl | D16: RCP45 | E16: N1 | F16: 2050 | G16: update electricity only+wrong year in db.name | H16: market group for electricity, high voltage | I16: 0.04624693 | J16: kilowatt hour | K16: 0.00061648481 | L16: kg CO2-Eq | M16: 0.042826737 | N16: 0.013330286 | O16: 0.92604498 | Q16: 14 | R16: ei_cutoff_3.9_tiam-ucl_SSP2-RCP45_2050_Reference - N1 2025-05-15 | S16: tiam-ucl | T16: RCP45 | U16: N1 | V16: 2050 | X16: market group for electricity, high voltage | Y16: 0.04624693 | Z16: kilowatt hour | AA16: 0.00052412673 | AB16: kg CO2-Eq | AC16: 0.040669227 | AD16: 0.011333222 | AE16: 0.87939301 | AG16: =(K16-AA16)/AA16 -> 0.17621328 | AH16: =(N16-AD16)/('contrib an. aggreg'!$I$2/1000) -> 0.13873455
A17: 15 | B17: ei_cutoff_3.9_tiam-ucl_SSP2-RCP45_2020_Reference - N1 2025-05-22 - elec | C17: tiam-ucl | D17: RCP45 | E17: N1 | F17: 2050 | G17: update electricity only+wrong year in db.name | H17: market for electricity, high voltage, FE2050 | I17: 0.031242685 | J17: kilowatt hour | K17: 0.00044973402 | L17: kg CO2-Eq | M17: 0.031242685 | N17: 0.014394858 | O17: 1 | Q17: 15 | R17: ei_cutoff_3.9_tiam-ucl_SSP2-RCP45_2050_Reference - N1 2025-05-15 | S17: tiam-ucl | T17: RCP45 | U17: N1 | V17: 2050 | X17: market for electricity, high voltage, FE2050 | Y17: 0.031242685 | Z17: kilowatt hour | AA17: 0.00040264169 | AB17: kg CO2-Eq | AC17: 0.031242685 | AD17: 0.012887551 | AE17: 1 | AG17: =(K17-AA17)/AA17 -> 0.11695841 | AH17: =(N17-AD17)/('contrib an. aggreg'!$I$2/1000) -> 0.10471152
A18: 16 | B18: ei_cutoff_3.9_tiam-ucl_SSP2-RCP45_2020_Reference - N1 2025-05-22 - elec | C18: tiam-ucl | D18: RCP45 | E18: N1 | F18: 2050 | G18: update electricity only+wrong year in db.name | H18: transmission network construction, electricity, high voltage direct current aerial line | I18: 5.65e-09 | J18: kilometer | K18: 0.00073957432 | L18: kg CO2-Eq | M18: 0.051377673 | N18: 130898.11 | O18: 9093393.4 | Q18: 16 | R18: ei_cutoff_3.9_tiam-ucl_SSP2-RCP45_2050_Reference - N1 2025-05-15 | S18: tiam-ucl | T18: RCP45 | U18: N1 | V18: 2050 | X18: transmission network construction, electricity, high voltage direct current aerial line | Y18: 5.65e-09 | Z18: kilometer | AA18: 0.00057973314 | AB18: kg CO2-Eq | AC18: 0.044983965 | AD18: 102607.64 | AE18: 7961763.7 | AG18: =(K18-AA18)/AA18 -> 0.2757151
A19: 17 | B19: ei_cutoff_3.9_tiam-ucl_SSP2-RCP45_2020_Reference - N1 2025-05-22 - elec | C19: tiam-ucl | D19: RCP45 | E19: N1 | F19: 2050 | G19: update electricity only+wrong year in db.name | H19: transmission network construction, electricity, high voltage direct current land cable | I19: 3.86e-10 | J19: kilometer | K19: 5.9634682e-05 | L19: kg CO2-Eq | M19: 0.0041427766 | N19: 154493.99 | O19: 10732582 | Q19: 17 | R19: ei_cutoff_3.9_tiam-ucl_SSP2-RCP45_2050_Reference - N1 2025-05-15 | S19: tiam-ucl | T19: RCP45 | U19: N1 | V19: 2050 | X19: transmission network construction, electricity, high voltage direct current land cable | Y19: 3.86e-10 | Z19: kilometer | AA19: 5.4895931e-05 | AB19: kg CO2-Eq | AC19: 0.0042596093 | AD19: 142217.44 | AE19: 11035257 | AG19: =(K19-AA19)/AA19 -> 0.086322437
A20: 18 | B20: ei_cutoff_3.9_tiam-ucl_SSP2-RCP45_2020_Reference - N1 2025-05-22 - elec | C20: tiam-ucl | D20: RCP45 | E20: N1 | F20: 2050 | G20: update electricity only+wrong year in db.name | H20: transmission network construction, electricity, high voltage direct current subsea cable | I20: 3.47e-12 | J20: kilometer | K20: 5.1053444e-07 | L20: kg CO2-Eq | M20: 3.5466444e-05 | N20: 147128.08 | O20: 10220877 | Q20: 18 | R20: ei_cutoff_3.9_tiam-ucl_SSP2-RCP45_2050_Reference - N1 2025-05-15 | S20: tiam-ucl | T20: RCP45 | U20: N1 | V20: 2050 | X20: transmission network construction, electricity, high voltage direct current subsea cable | Y20: 3.47e-12 | Z20: kilometer | AA20: 3.4279273e-07 | AB20: kg CO2-Eq | AC20: 2.6598749e-05 | AD20: 98787.53 | AE20: 7665345.5 | AG20: =(K20-AA20)/AA20 -> 0.4893386
A21: 19 | B21: ei_cutoff_3.9_tiam-ucl_SSP2-RCP45_2020_Reference - N1 2025-05-22 - elec | C21: tiam-ucl | D21: RCP45 | E21: N1 | F21: 2050 | G21: update electricity only+wrong year in db.name | H21: Dinitrogen monoxide('air',) | I21: 5e-06 | J21: kilogram | Q21: 19 | R21: ei_cutoff_3.9_tiam-ucl_SSP2-RCP45_2050_Reference - N1 2025-05-15 | S21: tiam-ucl | T21: RCP45 | U21: N1 | V21: 2050 | X21: Dinitrogen monoxide('air',) | Y21: 5e-06 | Z21: kilogram
A22: 20 | B22: ei_cutoff_3.9_tiam-ucl_SSP2-RCP45_2020_Reference - N1 2025-05-22 - elec | C22: tiam-ucl | D22: RCP45 | E22: N1 | F22: 2050 | G22: update electricity only+wrong year in db.name | H22: Ozone('air',) | I22: 4.16e-06 | J22: kilogram | Q22: 20 | R22: ei_cutoff_3.9_tiam-ucl_SSP2-RCP45_2050_Reference - N1 2025-05-15 | S22: tiam-ucl | T22: RCP45 | U22: N1 | V22: 2050 | X22: Ozone('air',) | Y22: 4.16e-06 | Z22: kilogram
B24: db_name | C24: model | D24: IAM scenario | E24: FR scenario | F24: year | G24: warning | H24: act | I24: amount | J24: unit amount | K24: impact | L24: unit impact | M24: % impact | N24: absolute impact | O24: absolute impact/impact elec | R24: db_name | S24: model | T24: IAM scenario | U24: FR scenario | V24: year | W24: warning | X24: act | Y24: amount | Z24: unit amount | AA24: impact | AB24: unit impact | AC24: % impact | AD24: absolute impact | AE24: absolute impact/impact elec | AG24: impact 1 kWh | AH24: diff in absolute impact / total impact of consumption mix
A25: 0 | B25: ei_cutoff_3.9_tiam-ucl_SSP2-Base_2050_Reference - N1 2025-05-22 - elec | C25: tiam-ucl | D25: Base | E25: N1 | F25: 2050 | G25: update electricity only | H25: electricity production, nuclear, pressure water reactor | I25: 0.12384131 | J25: kilowatt hour | K25: 0.00069077278 | L25: kg CO2-Eq | M25: 0.023809098 | N25: 0.0055778865 | O25: 0.19225489 | Q25: 0 | R25: ei_cutoff_3.9_tiam-ucl_SSP2-Base_2050_Reference - N1 2025-05-15 | S25: tiam-ucl | T25: Base | U25: N1 | V25: 2050 | X25: electricity production, nuclear, pressure water reactor | Y25: 0.12384131 | Z25: kilowatt hour | AA25: 0.00071700885 | AB25: kg CO2-Eq | AC25: 0.025356266 | AD25: 0.0057897388 | AE25: 0.20474804 | AG25: =(K25-AA25)/AA25 -> -0.036590992 | AH25: =(N25-AD25)/('contrib an. aggreg'!$I$8/1000) -> -0.007301984
A26: 1 | B26: ei_cutoff_3.9_tiam-ucl_SSP2-Base_2050_Reference - N1 2025-05-22 - elec | C26: tiam-ucl | D26: Base | E26: N1 | F26: 2050 | G26: update electricity only | H26: electricity production, Evolutionary Power Reactor (EPR) | I26: 0.12008855 | J26: kilowatt hour | K26: 0.00053071944 | L26: kg CO2-Eq | M26: 0.018292485 | N26: 0.004419401 | O26: 0.15232498 | Q26: 1 | R26: ei_cutoff_3.9_tiam-ucl_SSP2-Base_2050_Reference - N1 2025-05-15 | S26: tiam-ucl | T26: Base | U26: N1 | V26: 2050 | X26: electricity production, Evolutionary Power Reactor (EPR) | Y26: 0.12008855 | Z26: kilowatt hour | AA26: 0.00054859335 | AB26: kg CO2-Eq | AC26: 0.019400428 | AD26: 0.0045682404 | AE26: 0.16155103 | AG26: =(K26-AA26)/AA26 -> -0.032581346 | AH26: =(N26-AD26)/('contrib an. aggreg'!$I$8/1000) -> -0.0051300983
A27: 2 | B27: ei_cutoff_3.9_tiam-ucl_SSP2-Base_2050_Reference - N1 2025-05-22 - elec | C27: tiam-ucl | D27: Base | E27: N1 | F27: 2050 | G27: update electricity only | H27: electricity production, hydro, run-of-river | I27: 0.070702131 | J27: kilowatt hour | K27: 0.00026836259 | L27: kg CO2-Eq | M27: 0.0092497436 | N27: 0.003795679 | O27: 0.13082694 | Q27: 2 | R27: ei_cutoff_3.9_tiam-ucl_SSP2-Base_2050_Reference - N1 2025-05-15 | S27: tiam-ucl | T27: Base | U27: N1 | V27: 2050 | X27: electricity production, hydro, run-of-river | Y27: 0.070702131 | Z27: kilowatt hour | AA27: 0.00027128036 | AB27: kg CO2-Eq | AC27: 0.0095935452 | AD27: 0.0038369474 | AE27: 0.13568962 | AG27: =(K27-AA27)/AA27 -> -0.010755536 | AH27: =(N27-AD27)/('contrib an. aggreg'!$I$8/1000) -> -0.0014224127
A28: 3 | B28: ei_cutoff_3.9_tiam-ucl_SSP2-Base_2050_Reference - N1 2025-05-22 - elec | C28: tiam-ucl | D28: Base | E28: N1 | F28: 2050 | G28: update electricity only | H28: electricity production, hydro, reservoir, alpine region | I28: 0.013467073 | J28: kilowatt hour | K28: 7.8124656e-05 | L28: kg CO2-Eq | M28: 0.0026927488 | N28: 0.005801161 | O28: 0.19995056 | Q28: 3 | R28: ei_cutoff_3.9_tiam-ucl_SSP2-Base_2050_Reference - N1 2025-05-15 | S28: tiam-ucl | T28: Base | U28: N1 | V28: 2050 | X28: electricity production, hydro, reservoir, alpine region | Y28: 0.013467073 | Z28: kilowatt hour | AA28: 7.8503122e-05 | AB28: kg CO2-Eq | AC28: 0.0027761806 | AD28: 0.0058292641 | AE28: 0.20614581 | AG28: =(K28-AA28)/AA28 -> -0.0048210371 | AH28: =(N28-AD28)/('contrib an. aggreg'!$I$8/1000) -> -0.00096863893
A29: 4 | B29: ei_cutoff_3.9_tiam-ucl_SSP2-Base_2050_Reference - N1 2025-05-22 - elec | C29: tiam-ucl | D29: Base | E29: N1 | F29: 2050 | G29: update electricity only | H29: electricity production, photovoltaic | I29: 0.19353556 | J29: kilowatt hour | K29: 0.0034685218 | L29: kg CO2-Eq | M29: 0.11955071 | N29: 0.017921884 | O29: 0.6177196 | Q29: 4 | R29: ei_cutoff_3.9_tiam-ucl_SSP2-Base_2050_Reference - N1 2025-05-15 | S29: tiam-ucl | T29: Base | U29: N1 | V29: 2050 | X29: electricity production, photovoltaic | Y29: 0.19353556 | Z29: kilowatt hour | AA29: 0.0033840001 | AB29: kg CO2-Eq | AC29: 0.11967161 | AD29: 0.01748516 | AE29: 0.61834433 | AG29: =(K29-AA29)/AA29 -> 0.024976851 | AH29: =(N29-AD29)/('contrib an. aggreg'!$I$8/1000) -> 0.015052721
A30: 5 | B30: ei_cutoff_3.9_tiam-ucl_SSP2-Base_2050_Reference - N1 2025-05-22 - elec | C30: tiam-ucl | D30: Base | E30: N1 | F30: 2050 | G30: update electricity only | H30: electricity production, wind, 1-3MW turbine, onshore | I30: 0.15721413 | J30: kilowatt hour | K30: 0.0018760777 | L30: kg CO2-Eq | M30: 0.064663399 | N30: 0.011933263 | O30: 0.4113078 | Q30: 5 | R30: ei_cutoff_3.9_tiam-ucl_SSP2-Base_2050_Reference - N1 2025-05-15 | S30: tiam-ucl | T30: Base | U30: N1 | V30: 2050 | X30: electricity production, wind, 1-3MW turbine, onshore | Y30: 0.15721413 | Z30: kilowatt hour | AA30: 0.0018769348 | AB30: kg CO2-Eq | AC30: 0.066375831 | AD30: 0.011938716 | AE30: 0.42220015 | AG30: =(K30-AA30)/AA30 -> -0.00045669655 | AH30: =(N30-AD30)/('contrib an. aggreg'!$I$8/1000) -> -0.00018792868
A31: 6 | B31: ei_cutoff_3.9_tiam-ucl_SSP2-Base_2050_Reference - N1 2025-05-22 - elec | C31: tiam-ucl | D31: Base | E31: N1 | F31: 2050 | G31: update electricity only | H31: electricity production, wind, 1-3MW turbine, offshore | I31: 0.21471189 | J31: kilowatt hour | K31: 0.0027739698 | L31: kg CO2-Eq | M31: 0.095611348 | N31: 0.012919498 | O31: 0.44530068 | Q31: 6 | R31: ei_cutoff_3.9_tiam-ucl_SSP2-Base_2050_Reference - N1 2025-05-15 | S31: tiam-ucl | T31: Base | U31: N1 | V31: 2050 | X31: electricity production, wind, 1-3MW turbine, offshore | Y31: 0.21471189 | Z31: kilowatt hour | AA31: 0.0027687999 | AB31: kg CO2-Eq | AC31: 0.097915705 | AD31: 0.01289542 | AE31: 0.456033 | AG31: =(K31-AA31)/AA31 -> 0.0018671745 | AH31: =(N31-AD31)/('contrib an. aggreg'!$I$8/1000) -> 0.0008299045
A32: 7 | B32: ei_cutoff_3.9_tiam-ucl_SSP2-Base_2050_Reference - N1 2025-05-22 - elec | C32: tiam-ucl | D32: Base | E32: N1 | F32: 2050 | G32: update electricity only | H32: heat and power co-generation, wood chips, 6667 kW | I32: 0.013134685 | J32: kilowatt hour | K32: 0.00074303389 | L32: kg CO2-Eq | M32: 0.025610399 | N32: 0.056570364 | O32: 1.9498298 | Q32: 7 | R32: ei_cutoff_3.9_tiam-ucl_SSP2-Base_2050_Reference - N1 2025-05-15 | S32: tiam-ucl | T32: Base | U32: N1 | V32: 2050 | X32: heat and power co-generation, wood chips, 6667 kW | Y32: 0.013134685 | Z32: kilowatt hour | AA32: 0.00060279948 | AB32: kg CO2-Eq | AC32: 0.021317371 | AD32: 0.045893716 | AE32: 1.6229831 | AG32: =(K32-AA32)/AA32 -> 0.23263858 | AH32: =(N32-AD32)/('contrib an. aggreg'!$I$8/1000) -> 0.36799564
A33: 8 | B33: ei_cutoff_3.9_tiam-ucl_SSP2-Base_2050_Reference - N1 2025-05-22 - elec | C33: tiam-ucl | D33: Base | E33: N1 | F33: 2050 | G33: update electricity only | H33: treatment of municipal solid waste, incineration | I33: 0.0024124931 | J33: kilowatt hour | K33: 0 | L33: kg CO2-Eq | M33: 0 | N33: 0 | O33: 0 | Q33: 8 | R33: ei_cutoff_3.9_tiam-ucl_SSP2-Base_2050_Reference - N1 2025-05-15 | S33: tiam-ucl | T33: Base | U33: N1 | V33: 2050 | X33: treatment of municipal solid waste, incineration | Y33: 0.0024124931 | Z33: kilowatt hour | AA33: 0 | AB33: kg CO2-Eq | AC33: 0 | AD33: 0 | AE33: 0 | AH33: =(N33-AD33)/('contrib an. aggreg'!$I$8/1000) -> 0
A34: 9 | B34: ei_cutoff_3.9_tiam-ucl_SSP2-Base_2050_Reference - N1 2025-05-22 - elec | C34: tiam-ucl | D34: Base | E34: N1 | F34: 2050 | G34: update electricity only | H34: electricity production, natural gas, combined cycle power plant | I34: 0.00067013697 | J34: kilowatt hour | K34: 4.7098671e-05 | L34: kg CO2-Eq | M34: 0.0016233657 | N34: 0.070282156 | O34: 2.4224387 | Q34: 9 | R34: ei_cutoff_3.9_tiam-ucl_SSP2-Base_2050_Reference - N1 2025-05-15 | S34: tiam-ucl | T34: Base | U34: N1 | V34: 2050 | X34: electricity production, natural gas, combined cycle power plant | Y34: 0.00067013697 | Z34: kilowatt hour | AA34: 2.1385727e-05 | AB34: kg CO2-Eq | AC34: 0.00075628378 | AD34: 0.031912471 | AE34: 1.128551 | AG34: =(K34-AA34)/AA34 -> 1.2023414 | AH34: =(N34-AD34)/('contrib an. aggreg'!$I$8/1000) -> 1.3225008
A35: 10 | B35: ei_cutoff_3.9_tiam-ucl_SSP2-Base_2050_Reference - N1 2025-05-22 - elec | C35: tiam-ucl | D35: Base | E35: N1 | F35: 2050 | G35: update electricity only | H35: electricity production, hydro, pumped storage, FE2050 | I35: 0.021842905 | J35: kilowatt hour | K35: 0.00082054699 | L35: kg CO2-Eq | M35: 0.028282069 | N35: 0.037565837 | O35: 1.2947943 | Q35: 10 | R35: ei_cutoff_3.9_tiam-ucl_SSP2-Base_2050_Reference - N1 2025-05-15 | S35: tiam-ucl | T35: Base | U35: N1 | V35: 2050 | X35: electricity production, hydro, pumped storage, FE2050 | Y35: 0.021842905 | Z35: kilowatt hour | AA35: 0.00080356946 | AB35: kg CO2-Eq | AC35: 0.028417391 | AD35: 0.036788581 | AE35: 1.3009896 | AG35: =(K35-AA35)/AA35 -> 0.021127641 | AH35: =(N35-AD35)/('contrib an. aggreg'!$I$8/1000) -> 0.026789942
A36: 11 | B36: ei_cutoff_3.9_tiam-ucl_SSP2-Base_2050_Reference - N1 2025-05-22 - elec | C36: tiam-ucl | D36: Base | E36: N1 | F36: 2050 | G36: update electricity only | H36: electricity production, from hydrogen, with gas turbine, for grid-balancing, FE2050 | I36: 0.0082453349 | J36: kilowatt hour | K36: 0.00080999567 | L36: kg CO2-Eq | M36: 0.027918393 | N36: 0.098236843 | O36: 3.3859623 | Q36: 11 | R36: ei_cutoff_3.9_tiam-ucl_SSP2-Base_2050_Reference - N1 2025-05-15 | S36: tiam-ucl | T36: Base | U36: N1 | V36: 2050 | X36: electricity production, from hydrogen, with gas turbine, for grid-balancing, FE2050 | Y36: 0.0082453349 | Z36: kilowatt hour | AA36: 0.00085565741 | AB36: kg CO2-Eq | AC36: 0.030259427 | AD36: 0.10377473 | AE36: 3.6698845 | AG36: =(K36-AA36)/AA36 -> -0.053364513 | AH36: =(N36-AD36)/('contrib an. aggreg'!$I$8/1000) -> -0.19087625
A37: 12 | B37: ei_cutoff_3.9_tiam-ucl_SSP2-Base_2050_Reference - N1 2025-05-22 - elec | C37: tiam-ucl | D37: Base | E37: N1 | F37: 2050 | G37: update electricity only | H37: electricity production, from vehicle-to-grid, FE2050 | I37: 0.002748445 | J37: kilowatt hour | K37: 0.00011556974 | L37: kg CO2-Eq | M37: 0.0039833812 | N37: 0.042049139 | O37: 1.4493218 | Q37: 12 | R37: ei_cutoff_3.9_tiam-ucl_SSP2-Base_2050_Reference - N1 2025-05-15 | S37: tiam-ucl | T37: Base | U37: N1 | V37: 2050 | X37: electricity production, from vehicle-to-grid, FE2050 | Y37: 0.002748445 | Z37: kilowatt hour | AA37: 0.00011326625 | AB37: kg CO2-Eq | AC37: 0.0040055422 | AD37: 0.041211032 | AE37: 1.4573849 | AG37: =(K37-AA37)/AA37 -> 0.020336968 | AH37: =(N37-AD37)/('contrib an. aggreg'!$I$8/1000) -> 0.028887331
A38: 13 | B38: ei_cutoff_3.9_tiam-ucl_SSP2-Base_2050_Reference - N1 2025-05-22 - elec | C38: tiam-ucl | D38: Base | E38: N1 | F38: 2050 | G38: update electricity only | H38: electricity supply, high voltage, from vanadium-redox flow battery system, FE2050 | I38: 0.011138435 | J38: kilowatt hour | K38: 0.00065919496 | L38: kg CO2-Eq | M38: 0.022720694 | N38: 0.05918201 | O38: 2.0398462 | Q38: 13 | R38: ei_cutoff_3.9_tiam-ucl_SSP2-Base_2050_Reference - N1 2025-05-15 | S38: tiam-ucl | T38: Base | U38: N1 | V38: 2050 | X38: electricity supply, high voltage, from vanadium-redox flow battery system, FE2050 | Y38: 0.011138435 | Z38: kilowatt hour | AA38: 0.00065132379 | AB38: kg CO2-Eq | AC38: 0.023033382 | AD38: 0.058475342 | AE38: 2.0679191 | AG38: =(K38-AA38)/AA38 -> 0.012084879 | AH38: =(N38-AD38)/('contrib an. aggreg'!$I$8/1000) -> 0.024356943
A39: 14 | B39: ei_cutoff_3.9_tiam-ucl_SSP2-Base_2050_Reference - N1 2025-05-22 - elec | C39: tiam-ucl | D39: Base | E39: N1 | F39: 2050 | G39: update electricity only | H39: market group for electricity, high voltage | I39: 0.04624693 | J39: kilowatt hour | K39: 0.013047342 | L39: kg CO2-Eq | M39: 0.44970711 | N39: 0.28212342 | O39: 9.7240426 | Q39: 14 | R39: ei_cutoff_3.9_tiam-ucl_SSP2-Base_2050_Reference - N1 2025-05-15 | S39: tiam-ucl | T39: Base | U39: N1 | V39: 2050 | X39: market group for electricity, high voltage | Y39: 0.04624693 | Z39: kilowatt hour | AA39: 0.012511673 | AB39: kg CO2-Eq | AC39: 0.4424622 | AD39: 0.27054063 | AE39: 9.5673855 | AG39: =(K39-AA39)/AA39 -> 0.042813488 | AH39: =(N39-AD39)/('contrib an. aggreg'!$I$8/1000) -> 0.39922785
A40: 15 | B40: ei_cutoff_3.9_tiam-ucl_SSP2-Base_2050_Reference - N1 2025-05-22 - elec | C40: tiam-ucl | D40: Base | E40: N1 | F40: 2050 | G40: update electricity only | H40: market for electricity, high voltage, FE2050 | I40: 0.031242685 | J40: kilowatt hour | K40: 0.00090644326 | L40: kg CO2-Eq | M40: 0.031242685 | N40: 0.029012976 | O40: 1 | Q40: 15 | R40: ei_cutoff_3.9_tiam-ucl_SSP2-Base_2050_Reference - N1 2025-05-15 | S40: tiam-ucl | T40: Base | U40: N1 | V40: 2050 | X40: market for electricity, high voltage, FE2050 | Y40: 0.031242685 | Z40: kilowatt hour | AA40: 0.00088346137 | AB40: kg CO2-Eq | AC40: 0.031242685 | AD40: 0.028277384 | AE40: 1 | AG40: =(K40-AA40)/AA40 -> 0.026013463 | AH40: =(N40-AD40)/('contrib an. aggreg'!$I$8/1000) -> 0.02535392
A41: 16 | B41: ei_cutoff_3.9_tiam-ucl_SSP2-Base_2050_Reference - N1 2025-05-22 - elec | C41: tiam-ucl | D41: Base | E41: N1 | F41: 2050 | G41: update electricity only | H41: transmission network construction, electricity, high voltage direct current aerial line | I41: 5.65e-09 | J41: kilometer | K41: 0.0007472572 | L41: kg CO2-Eq | M41: 0.025755965 | N41: 132257.91 | O41: 4558577.9 | Q41: 16 | R41: ei_cutoff_3.9_tiam-ucl_SSP2-Base_2050_Reference - N1 2025-05-15 | S41: tiam-ucl | T41: Base | U41: N1 | V41: 2050 | X41: transmission network construction, electricity, high voltage direct current aerial line | Y41: 5.65e-09 | Z41: kilometer | AA41: 0.00075603688 | AB41: kg CO2-Eq | AC41: 0.026736451 | AD41: 133811.84 | AE41: 4732115.2 | AG41: =(K41-AA41)/AA41 -> -0.011612765
...
